Workbook
Name Button_1: "X2160060266_Sheet3_List"
Name KRT: #REF!
Name Manufacturing: Validation!$C$2:$C$115
Name Obligation: #REF!
Name Product: #REF!
Name Services: Validation!$I$2:$I$50
Name tata: #REF!
Name Teja: '[1]Oblig Details & RTR'!$OQ$1:$OQ$6
Name Trading: Validation!$F$2:$F$118
Name Type: #REF!
Name X2160060266_Sheet3_List: #REF!

Sheet BasicInput
B1: Segment (select from dropdown): | C1: Prime | E1: Customer Type (select from dropdown): | H1: Self-employed Non-Professional (SENP)
B2: Deal Number | C2: 3000023573
A4: Parties to the Loan
A5: S. No. | B5: Name | C5: Constitution (select from dropdown) | D5: Capacity (Applicant / Co-applicant / Guarantor) | E5: Age at the time of | G5: Relationship with Applicant | H5: CIBIL Score | I5: Income Considered (Y / N) | J5: Property Ownership (Y / N)
E6: Application | F6: Maturity
A7: 1 | B7: SONA NAVANI | C7: Individual | D7: APPLICANT | E7: =2024-1976 -> 48 | F7: =E7+20 -> 68 | G7: SELF | H7: 761 | I7: Y | J7: Y
A8: 2 | B8: NITIN | C8: Individual | D8: CO APPLICANT | E8: =2024-1974 -> 50 | F8: =E8+20 -> 70 | G8: SPOUSE | H8: 734 | I8: N | J8: N
A9: 3
A10: 4
A11: 5
A12: 6
A13: 7
A14: 8
A15: 9
A16: 10
A19: Proposed Loan Break-up
A21: S. No. | B21: Type of Loan | C21: Nature of Transaction | D21: Loan Amount (Rs.) | E21: Tenure (Months) | F21: Proposed ROI | G21: EMI (Rs.) | H21: PF-0.25%
A22: 1 | B22: Home Loan | C22: Resale (Normal) | D22: 1500000 | E22: 240 | F22: 0.105 | G22: =IFERROR(CEILING(PMT(F22/12,E22,-D22),1),0) -> 14976 | H22: Industrial Check | I22: =IF(AND(B22="",B23="",B24="",B25="",B26=""),"",IF(OR(B22=Validation!A29,B22=Validation!A36,B23=Validation!A29,B23=Validation!A36,B24=Validation!A29,B24=Validation!A36,B25=Validation!A29,B25=Validation!A36,B26=Validation!A29,B26=Validation!A36),"Y","N")) -> N | J22: =IF(B22="",0,IF(AND(B22=Validation!$A$37,OR($H$28="IndlGPL",$H$28="IndlGPLIns",$H$28="LAPGPL",$H$28="LAPGPLIns")),60,IF(AND(B22=Validation!$A$37,OR($H$28="HLGPL",$H$28="HLGPLIns",$H$28="GPL",$H$28="GPLIns")),120,IF($H$28="Indl",120,IF($H$28="LAP",240,360))))) -> 360 | K22: =IFERROR(IF(AND(H1="Salaried",OR(B22=Validation!A19,B22=Validation!A22,B22=Validation!A25,B22=Validation!A38)),360,VLOOKUP(B22,Validation!$A$19:$B$38,2,0)),0) -> 240
A23: 2 | G23: =IFERROR(CEILING(PMT(F23/12,E23,-D23),1),0) -> 0 | H23: LAP/Comm Check | I23: =IF(AND(B22="",B23="",B24="",B25="",B26=""),"",IF(OR(B22=Validation!A27,B22=Validation!A28,B22=Validation!A30,B22=Validation!A31,B22=Validation!A32,B22=Validation!A33,B22=Validation!A35,B23=Validation!A27,B23=Validation!A28,B23=Validation!A30,B23=Validation!A31,B23=Validation!A32,B23=Validation!A33,B23=Validation!A35,B24=Validation!A27,B24=Validation!A28,B24=Validation!A30,B24=Validation!A31,B24=Validation!A32,B24=Validation!A33,B24=Validation!A35,B25=Validation!A27,B25=Validation!A28,B25=Validation!A30,B25=Validation!A31,B25=Validation!A32,B25=Validation!A33,B25=Validation!A35,B26=Validation!A27,B26=Validation!A28,B26=Validation!A30,B26=Validation!A31,B26=Validation!A32,B26=Validation!A33,B26=Validation!A35),"Y","N")) -> N | J23: =IF(B23="",0,IF(AND(B23=Validation!$A$37,OR($H$28="IndlGPL",$H$28="IndlGPLIns",$H$28="LAPGPL",$H$28="LAPGPLIns")),60,IF(AND(B23=Validation!$A$37,OR($H$28="HLGPL",$H$28="HLGPLIns",$H$28="GPL",$H$28="GPLIns")),120,IF($H$28="Indl",120,IF($H$28="LAP",240,360))))) -> 0 | K23: =IFERROR(IF(AND(H2="Salaried",OR(B23=Validation!A20,B23=Validation!A23,B23=Validation!A26,B23=Validation!A39)),360,VLOOKUP(B23,Validation!$A$19:$B$38,2,0)),0) -> 0
A24: 3 | G24: =IFERROR(CEILING(PMT(F24/12,E24,-D24),1),0) -> 0 | H24: GPL Check | I24: =IF(AND(B22="",B23="",B24="",B25="",B26=""),"",IF(OR(B22=Validation!A37,B23=Validation!A37,B24=Validation!A37,B25=Validation!A37,B26=Validation!A37),"Y","N")) -> N | J24: =IF(B24="",0,IF(AND(B24=Validation!$A$37,OR($H$28="IndlGPL",$H$28="IndlGPLIns",$H$28="LAPGPL",$H$28="LAPGPLIns")),60,IF(AND(B24=Validation!$A$37,OR($H$28="HLGPL",$H$28="HLGPLIns",$H$28="GPL",$H$28="GPLIns")),120,IF($H$28="Indl",120,IF($H$28="LAP",240,360))))) -> 0 | K24: =IFERROR(IF(AND(H3="Salaried",OR(B24=Validation!A21,B24=Validation!A24,B24=Validation!A27,B24=Validation!A40)),360,VLOOKUP(B24,Validation!$A$19:$B$38,2,0)),0) -> 0
A25: 4 | G25: =IFERROR(CEILING(PMT(F25/12,E25,-D25),1),0) -> 0 | H25: Insurance Check | I25: =IF(AND(B22="",B23="",B24="",B25="",B26=""),"",IF(OR(B22=Validation!A38,B23=Validation!A38,B24=Validation!A38,B25=Validation!A38,B26=Validation!A38),"Y","N")) -> N | J25: =IF(B25="",0,IF(AND(B25=Validation!$A$37,OR($H$28="IndlGPL",$H$28="IndlGPLIns",$H$28="LAPGPL",$H$28="LAPGPLIns")),60,IF(AND(B25=Validation!$A$37,OR($H$28="HLGPL",$H$28="HLGPLIns",$H$28="GPL",$H$28="GPLIns")),120,IF($H$28="Indl",120,IF($H$28="LAP",240,360))))) -> 0 | K25: =IFERROR(IF(AND(H4="Salaried",OR(B25=Validation!A22,B25=Validation!A25,B25=Validation!A28,B25=Validation!A41)),360,VLOOKUP(B25,Validation!$A$19:$B$38,2,0)),0) -> 0
A26: 5 | G26: =IFERROR(CEILING(PMT(F26/12,E26,-D26),1),0) -> 0 | H26: HL Check | I26: =IF(AND(B22="",B23="",B24="",B25="",B26=""),"",IF(OR(B22=Validation!A19,B22=Validation!A20,B22=Validation!A21,B22=Validation!A22,B22=Validation!A23,B22=Validation!A24,B22=Validation!A25,B22=Validation!A26,B23=Validation!A19,B23=Validation!A20,B23=Validation!A21,B23=Validation!A22,B23=Validation!A23,B23=Validation!A24,B23=Validation!A25,B23=Validation!A26,B24=Validation!A19,B24=Validation!A20,B24=Validation!A21,B24=Validation!A22,B24=Validation!A23,B24=Validation!A24,B24=Validation!A25,B24=Validation!A26,B25=Validation!A19,B25=Validation!A20,B25=Validation!A21,B25=Validation!A22,B25=Validation!A23,B25=Validation!A24,B25=Validation!A25,B25=Validation!A26,B26=Validation!A19,B26=Validation!A20,B26=Validation!A21,B26=Validation!A22,B26=Validation!A23,B26=Validation!A24,B26=Validation!A25,B26=Validation!A26),"Y","N")) -> Y | J26: =IF(B26="",0,IF(AND(B26=Validation!$A$37,OR($H$28="IndlGPL",$H$28="IndlGPLIns",$H$28="LAPGPL",$H$28="LAPGPLIns")),60,IF(AND(B26=Validation!$A$37,OR($H$28="HLGPL",$H$28="HLGPLIns",$H$28="GPL",$H$28="GPLIns")),120,IF($H$28="Indl",120,IF($H$28="LAP",240,360))))) -> 0 | K26: =IFERROR(IF(AND(H5="Salaried",OR(B26=Validation!A23,B26=Validation!A26,B26=Validation!A29,B26=Validation!A42)),360,VLOOKUP(B26,Validation!$A$19:$B$38,2,0)),0) -> 0
A27: Total | D27: =SUM(D22:D26) -> 1500000 | E27: =IFERROR(SUMPRODUCT($D$22:$D$26,$E$22:$E$26)/$D$27,0) -> 240 | F27: =IFERROR(SUMPRODUCT($D$22:$D$26,$F$22:$F$26)/$D$27,0) -> 0.105 | G27: =SUM(G22:G26) -> 14976
B28: =COUNTIF($B$22:$B$26,Validation!$A$19)+COUNTIF($B$22:$B$26,Validation!$A$20)+COUNTIF($B$22:$B$26,Validation!$A$21)+COUNTIF($B$22:$B$26,Validation!$A$22)+COUNTIF($B$22:$B$26,Validation!$A$23)+COUNTIF($B$22:$B$26,Validation!$A$24)+COUNTIF($B$22:$B$26,Validation!$A$25)+COUNTIF($B$22:$B$26,Validation!$A$26) -> 1 | C28: Loan (excl GPL & Insurance) | D28: =D27-SUMIF(B22:B26,Validation!A37,D22:D26)-SUMIF(B22:B26,Validation!A38,D22:D26) -> 1500000 | F28: =G27/D27 -> 0.009984 | G28: =G27-SUMIF(B22:B26,Validation!A37,G22:G26)-SUMIF(B22:B26,Validation!A38,G22:G26) -> 14976 | H28: =IF(AND(I22="Y",I24="Y",I25="Y"),"IndlGPLIns",IF(AND(I22="Y",I24="Y"),"IndlGPL",IF(AND(I22="Y",I25="Y"),"IndlIns",IF(I22="Y","Indl",IF(AND(I23="Y",I24="Y",I25="Y"),"LAPGPLIns",IF(AND(I23="Y",I24="Y"),"LAPGPL",IF(AND(I23="Y",I25="Y"),"LAPIns",IF(I23="Y","LAP",IF(AND(I26="Y",I24="Y",I25="Y"),"HLGPLIns",IF(AND(I26="Y",I24="Y"),"HLGPL",IF(AND(I26="Y",I25="Y"),"HLIns",IF(I26="Y","HL",IF(AND(I24="Y",I25="Y"),"GPLIns",IF(I24="Y","GPL",IF(I25="Y","Ins",""))))))))))))))) -> HL
A31: Property Details [Provide estimated details if not finalized]
A33: S. No. | B33: Property Address | C33: Property Type | D33: Owner(s) / Proposed Owner(s) | E33: Area (Sq Ft) | F33: Usage / Proposed Usage | G33: Whether in APF Project? | H33: Our existing exposure against the Property (Rs.) | I33: Valuation 1 (Rs.) | J33: Valuation 2 (Rs.) | K33: Agreement Value / Property Cost (incl Amenities) as may be applicable (Rs.) | L33: Stage of Construction | M33: Difference % in Valuations | N33: Valuation to be considered (Rs.)
A34: 1 | B34: B-54,KEDAR NAGAR, Shahganj,Agra,KEDAR NAGAR,Agra,Agra,Uttar Pradesh,282010 | C34: Residential House | D34: SONA NAVANI | E34: =40*9 -> 360 | F34: Self-occupation | G34: N | H34: 0 | I34: 0 | J34: 0 | K34: 1900000 | L34: 1 | M34: =IF(AND(I34="",J34=""),"",IF(OR(I34="",J34=""),"N.A.",IF(I34>=J34,(I34-J34)/J34,(J34-I34)/I34))) -> #DIV/0! | N34: =IF(AND(G34="Y",OR($H$28="HL",$H$28="HLGPL",$H$28="HLIns",$H$28="HLGPLIns")),IF(K34="","Agreement Value / Property Cost required",IF(AND(I34<>"",J34<>""),MIN(I34,J34,K34),IF(I34<>"",MIN(I34,K34),IF(J34<>"",MIN(J34,K34),"")))),IF(AND(OR(G34="N",G34=""),OR($H$28="HL",$H$28="HLGPL",$H$28="HLIns",$H$28="HLGPLIns")),IF(K34="","Agreement Value / Property Cost required",IF(AND(I34<>"",J34<>""),MIN(I34,J34),IF(AND(I34<>"",$D$27<=5000000),I34,IF(AND(J34<>"",$D$27<=5000000),J34,"")))),IF(AND(OR(I34="",J34=""),$D$27>5000000),"Two Valuations required",IF(AND(I34<>"",J34=""),I34,IF(AND(J34<>"",I34=""),J34,MIN(I34,J34)))))) -> 0 | O34: =IF(OR(I34="",J34=""),"",IF(M34>15%,"3rd Valuation to be fired if Lowest Valuation not sufficient for Eligibility","")) -> #DIV/0!
A35: 2 | M35: =IF(AND(I35="",J35=""),"",IF(OR(I35="",J35=""),"N.A.",IF(I35>=J35,(I35-J35)/J35,(J35-I35)/I35))) | N35: =IF(AND(G35="Y",OR($H$28="HL",$H$28="HLGPL",$H$28="HLIns",$H$28="HLGPLIns")),IF(K35="","Agreement Value / Property Cost required",IF(AND(I35<>"",J35<>""),MIN(I35,J35,K35),IF(I35<>"",MIN(I35,K35),IF(J35<>"",MIN(J35,K35),"")))),IF(AND(OR(G35="N",G35=""),OR($H$28="HL",$H$28="HLGPL",$H$28="HLIns",$H$28="HLGPLIns")),IF(K35="","Agreement Value / Property Cost required",IF(AND(I35<>"",J35<>""),MIN(I35,J35),IF(AND(I35<>"",$D$27<=5000000),I35,IF(AND(J35<>"",$D$27<=5000000),J35,"")))),IF(AND(OR(I35="",J35=""),$D$27>5000000),"Two Valuations required",IF(AND(I35<>"",J35=""),I35,IF(AND(J35<>"",I35=""),J35,MIN(I35,J35)))))) -> Agreement Value / Property Cost required | O35: =IF(OR(I35="",J35=""),"",IF(M35>15%,"3rd Valuation to be fired if Lowest Valuation not sufficient for Eligibility",""))
A36: 3 | M36: =IF(AND(I36="",J36=""),"",IF(OR(I36="",J36=""),"N.A.",IF(I36>=J36,(I36-J36)/J36,(J36-I36)/I36))) | N36: =IF(AND(G36="Y",OR($H$28="HL",$H$28="HLGPL",$H$28="HLIns",$H$28="HLGPLIns")),IF(K36="","Agreement Value / Property Cost required",IF(AND(I36<>"",J36<>""),MIN(I36,J36,K36),IF(I36<>"",MIN(I36,K36),IF(J36<>"",MIN(J36,K36),"")))),IF(AND(OR(G36="N",G36=""),OR($H$28="HL",$H$28="HLGPL",$H$28="HLIns",$H$28="HLGPLIns")),IF(K36="","Agreement Value / Property Cost required",IF(AND(I36<>"",J36<>""),MIN(I36,J36),IF(AND(I36<>"",$D$27<=5000000),I36,IF(AND(J36<>"",$D$27<=5000000),J36,"")))),IF(AND(OR(I36="",J36=""),$D$27>5000000),"Two Valuations required",IF(AND(I36<>"",J36=""),I36,IF(AND(J36<>"",I36=""),J36,MIN(I36,J36)))))) -> Agreement Value / Property Cost required | O36: =IF(OR(I36="",J36=""),"",IF(M36>15%,"3rd Valuation to be fired if Lowest Valuation not sufficient for Eligibility",""))
A37: 4 | M37: =IF(AND(I37="",J37=""),"",IF(OR(I37="",J37=""),"N.A.",IF(I37>=J37,(I37-J37)/J37,(J37-I37)/I37))) | N37: =IF(AND(G37="Y",OR($H$28="HL",$H$28="HLGPL",$H$28="HLIns",$H$28="HLGPLIns")),IF(K37="","Agreement Value / Property Cost required",IF(AND(I37<>"",J37<>""),MIN(I37,J37,K37),IF(I37<>"",MIN(I37,K37),IF(J37<>"",MIN(J37,K37),"")))),IF(AND(OR(G37="N",G37=""),OR($H$28="HL",$H$28="HLGPL",$H$28="HLIns",$H$28="HLGPLIns")),IF(K37="","Agreement Value / Property Cost required",IF(AND(I37<>"",J37<>""),MIN(I37,J37),IF(AND(I37<>"",$D$27<=5000000),I37,IF(AND(J37<>"",$D$27<=5000000),J37,"")))),IF(AND(OR(I37="",J37=""),$D$27>5000000),"Two Valuations required",IF(AND(I37<>"",J37=""),I37,IF(AND(J37<>"",I37=""),J37,MIN(I37,J37)))))) -> Agreement Value / Property Cost required | O37: =IF(OR(I37="",J37=""),"",IF(M37>15%,"3rd Valuation to be fired if Lowest Valuation not sufficient for Eligibility",""))
A38: 5 | M38: =IF(AND(I38="",J38=""),"",IF(OR(I38="",J38=""),"N.A.",IF(I38>=J38,(I38-J38)/J38,(J38-I38)/I38))) | N38: =IF(AND(G38="Y",OR($H$28="HL",$H$28="HLGPL",$H$28="HLIns",$H$28="HLGPLIns")),IF(K38="","Agreement Value / Property Cost required",IF(AND(I38<>"",J38<>""),MIN(I38,J38,K38),IF(I38<>"",MIN(I38,K38),IF(J38<>"",MIN(J38,K38),"")))),IF(AND(OR(G38="N",G38=""),OR($H$28="HL",$H$28="HLGPL",$H$28="HLIns",$H$28="HLGPLIns")),IF(K38="","Agreement Value / Property Cost required",IF(AND(I38<>"",J38<>""),MIN(I38,J38),IF(AND(I38<>"",$D$27<=5000000),I38,IF(AND(J38<>"",$D$27<=5000000),J38,"")))),IF(AND(OR(I38="",J38=""),$D$27>5000000),"Two Valuations required",IF(AND(I38<>"",J38=""),I38,IF(AND(J38<>"",I38=""),J38,MIN(I38,J38)))))) -> Agreement Value / Property Cost required | O38: =IF(OR(I38="",J38=""),"",IF(M38>15%,"3rd Valuation to be fired if Lowest Valuation not sufficient for Eligibility",""))
A39: Total | H39: =SUM(H34:H38) -> 0 | I39: =SUM(I34:I38) -> 0 | J39: =SUM(J34:J38) -> 0 | K39: =SUM(K34:K38) -> 1900000 | N39: =SUM(N34:N38) -> 0
F40: =IF(AND(F34="",F35="",F36="",F37="",F38=""),"",IF(OR(F34=Validation!A83,F35=Validation!A83,F36=Validation!A83,F37=Validation!A83,F38=Validation!A83),Validation!A83,IF(OR(F34=Validation!A82,F35=Validation!A82,F36=Validation!A82,F37=Validation!A82,F38=Validation!A82),Validation!A82,Validation!A81))) -> Self-occupation | I40: Final Valuation as per Norms: | J40: =N39 -> 0
A43: Additional Inputs for Eligibility Computation
D44: (Figs in Rs.)
A45: Particulars | D45: =PrimeConsolidated!C7 -> FY 2022-23 | E45: =PrimeConsolidated!D7 -> FY 2021-22
A46: Extraordinary Income like Profit on Sale of Asset (Capital Gain), One Time Interest, Donation, Insurance Claim, etc if not already excluded while arriving at PBT
A47: Extraordinary Expenses like Loss on Sale of Asset (Capital Loss), Loss on Theft, Donation made, etc deducted while arriving at PBT
A48: Salary Income (as per ITR if not considered while arriving at PBT) [Annualized]
A49: Rental Income {Existing Rentals as per ITR or Regd Lease Deed copy (>=3 months old) with Bank Credits / occupancy verified by Risk Team or in absence of Regd Lease Agreement, Avg of last 2 years Rentals as per ITRs} [Annualized]
...

Sheet SalariedEligibility
A1: Salaried Eligibility
A2: Loan Amount Requested (In INR) | B2: =BasicInput!$D$27 -> 1500000
A3: ROI | B3: =BasicInput!$F$27 -> 0.105
A4: Tenure - Months | B4: =BasicInput!$E$27 -> 240
A5: EMI on requested Loan Amount | B5: =BasicInput!$G$27 -> 14976
A7: Product - Property Type | B7: Home Loan
A8: Valuation Details | B8: Value
A9: Property Value - Valuation-1 | B9: =BasicInput!$I$39 -> 0
A10: Property Value - Valuation-2 | B10: =BasicInput!$J$39 -> 0
A11: Property Value - Final | B11: =IF($B$2<5000000,$B$9,MIN($B$9,$B$10)) -> 0
A13: Obligation Details | B13: Value
A14: Monthly Obligations to be considered in eligibility (excluding those against standalone Pension Income) | B14: ='ExistingLoans&Facilities&RTR'!$N$103 -> 0
A15: Obligations not to be considered in eligibility | B15: ='ExistingLoans&Facilities&RTR'!$N$105 -> 0
A17: Income Details
A18: Parameters | B18: % considered | C18: Previous Year | D18: Current Year | E18: Frequency | F18: Amount Considered
A19: Core Income (excluding Pension Income, if any)
A20: Basic | B20: 1 | D20: =ApplicantSalary!G8+'Co-app1Salary'!G8+'Co-app2Salary'!G8+'Co-app3Salary'!G8 -> 0 | E20: Monthly
A21: DA | B21: 1 | D21: =ApplicantSalary!G9+'Co-app1Salary'!G9+'Co-app2Salary'!G9+'Co-app3Salary'!G9 -> 0 | E21: Monthly
A22: HRA | B22: 1 | D22: =ApplicantSalary!G10+'Co-app1Salary'!G10+'Co-app2Salary'!G10+'Co-app3Salary'!G10 -> 0 | E22: Monthly
A23: Other Allowances | B23: 1 | D23: =SUM(ApplicantSalary!$G$11:$G$14)+SUM('Co-app1Salary'!$G$11:$G$14)+SUM('Co-app2Salary'!$G$11:$G$14)+SUM('Co-app3Salary'!$G$11:$G$14) -> 0 | E23: Monthly
A24: Gross Salary | B24: 1 | D24: =SUM(D20:D23) -> 0 | E24: Monthly
A25: Less - Deductions | B25: 1 | D25: =ApplicantSalary!G22+'Co-app1Salary'!G22+'Co-app2Salary'!G22+'Co-app3Salary'!G22 -> 0 | E25: Monthly
A26: Net Salary | B26: 1 | D26: =D24-D25 -> 0 | E26: Monthly | F26: =IF(E26="Monthly",(D26*B26)*12,(D26*B26)) -> 0
A27: Bonus & LTA
A28: Fixed Bonus | B28: 1 | C28: =ApplicantSalary!C27+'Co-app1Salary'!C27+'Co-app2Salary'!C27+'Co-app3Salary'!C27 -> 0 | D28: =ApplicantSalary!B27+'Co-app1Salary'!B27+'Co-app2Salary'!B27+'Co-app3Salary'!B27 -> 0 | E28: Annual | F28: =IF(E28="Monthly",(D28*B28)*12,(D28*B28)) -> 0
A29: Performance Linked Bonus | B29: 0.5 | C29: =ApplicantSalary!C28+'Co-app1Salary'!C28+'Co-app2Salary'!C28+'Co-app3Salary'!C28 -> 0 | D29: =ApplicantSalary!B28+'Co-app1Salary'!B28+'Co-app2Salary'!B28+'Co-app3Salary'!B28 -> 0 | E29: Annual | F29: =IF(E29="Monthly",(D29*B29)*12,(D29*B29)) -> 0
A30: LTA | B30: 1 | C30: =ApplicantSalary!C29+'Co-app1Salary'!C29+'Co-app2Salary'!C29+'Co-app3Salary'!C29 -> 0 | D30: =ApplicantSalary!B29+'Co-app1Salary'!B29+'Co-app2Salary'!B29+'Co-app3Salary'!B29 -> 0 | E30: Annual | F30: =IF(E30="Monthly",(D30*B30)*12,(D30*B30)) -> 0
A31: Pension Income
A32: Net Monthly Pension Income (not included in Core Income above and capped at 35% of Gross Monthly Income) | B32: 1 | E32: Monthly
A33: - Loan Obligations against Pension Income (not included in Obligations above) | B33: 1 | E33: Monthly
A34: Loan Tenure (months) for Pension Income portion
A35: Other Income
A36: Rental Income | B36: 0.5 | D36: =BasicInput!D49 -> 0 | E36: Annual | F36: =IF(E36="Monthly",(IF(C36=0,D36*B36*12,AVERAGE(C36*B36,D36*B36)*12)),IF(C36=0,D36*B36,(AVERAGE(C36*B36,D36*B36)))) -> 0
A37: Rental Income (Unregistered) | B37: 0.5 | E37: Annual | F37: =IF(E37="Monthly",(IF(C37=0,D37*B37*12,AVERAGE(C37*B37,D37*B37)*12)),IF(C37=0,D37*B37,(AVERAGE(C37*B37,D37*B37)))) -> 0
A38: Agricultural Income | B38: 0.5 | D38: =BasicInput!D50 -> 0 | E38: Annual | F38: =IF(E38="Monthly",AVERAGE(C38*B38,D38*B38)*12,AVERAGE(C38*B38,D38*B38)) -> 0
A39: Interest From FD / Dividend Income | B39: 1 | D39: =BasicInput!D51 -> 0 | E39: Annual | F39: =IF(E39="Monthly",AVERAGE(C39*B39,D39*B39)*12,AVERAGE(C39*B39,D39*B39)) -> 0
A40: Other Income | B40: 1 | D40: =BasicInput!D52 -> 0 | E40: Annual | F40: =IF(E40="Monthly",AVERAGE(C40*B40,D40*B40)*12,AVERAGE(C40*B40,D40*B40)) -> 0
A41: Other Income to be capped at 100% of the Core Income
A42: Rental Income from Property Mortgaged and Rentals escrowed with ABHFL
A43: Escrowed Rental Income | B43: 1 | D43: =BasicInput!D53 -> 0 | E43: Annual | F43: =IF(E43="Monthly",(D43*B43)*12,(D43*B43)) -> 0
...

Sheet ApplicantSalary
A1: Name:
A2: Employer Name:
A3: Designation:
A4: Date of Joining: | C4: Total Experience (Years):
B6: Rs.
A7: Component | B7: 45200 | C7: 45231 | D7: 45261 | E7: Standard Amount for calculation | F7: % to be considered | G7: Eligible Amount (Rs.)
A8: Basic | G8: =E8*F8 -> 0
A9: DA | G9: =E9*F9 -> 0
A10: HRA | G10: =E10*F10 -> 0
A11: Other Allowances | G11: =E11*F11 -> 0
A12: Variable Pay | G12: =E12*F12 -> 0
A13: Bonus | G13: =E13*F13 -> 0
A14: Arrears / Others | G14: =E14*F14 -> 0
A15: Gross Salary | B15: =SUM(B8:B14) -> 0 | C15: =SUM(C8:C14) -> 0 | D15: =SUM(D8:D14) -> 0 | E15: =SUM(E8:E14) -> 0 | G15: =SUM(G8:G14) -> 0
A16: Deductions:
A17: - PF | G17: =E17*F17 -> 0
A18: - Profession Tax | G18: =E18*F18 -> 0
A19: - Income Tax (TDS) | G19: =E19*F19 -> 0
A20: - Loan Deduction | G20: =E20*F20 -> 0
A21: - ESI / Other Deductions | G21: =E21*F21 -> 0
A22: Total Deductions | B22: =SUM(B17:B21) -> 0 | C22: =SUM(C17:C21) -> 0 | D22: =SUM(D17:D21) -> 0 | E22: =SUM(E17:E21) -> 0 | G22: =SUM(G17:G21) -> 0
A23: Net Salary | B23: =B15-B22 -> 0 | C23: =C15-C22 -> 0 | D23: =D15-D22 -> 0 | E23: =E15-E22 -> 0 | G23: =G15-G22 -> 0
A26: Annual Components (if excluded from above) | B26: Latest Year | C26: Previous Year | F26: % to be considered | G26: Eligible Amount (Rs.)
A27: Fixed Bonus | G27: =B27*F27 -> 0
A28: Performance Linked Bonus | G28: =B28*F28 -> 0
A29: LTA | G29: =B29*F29 -> 0
A32: Form 16 Part B Details, if any | G32: Latest Year
A33: Gross Salary as per Form 16
A34: Tax Deducted as per Form 16
A35: Net Salary as per Form 16
A36: Net Salary p.m. (as per Form 16) | G36: =G35/12 -> 0
A39: Salary, Bonus / Incentive, Reimbursement, or other credits from Employer
A41: Month | B41: Date | C41: Amount (Rs.) | D41: Remarks, if any

Sheet Co-app1Salary
A1: Name:
A2: Employer Name:
A3: Designation:
A4: Date of Joining: | B4: 43709 | C4: Total Experience (Years):
B6: Rs.
A7: Component | B7: Latest Month | C7: Previous Month | D7: Previous to previous month | E7: Standard Amount for calculation | F7: % to be considered | G7: Eligible Amount (Rs.)
A8: Basic | B8: 30000 | C8: 30000 | D8: 30000 | F8: 1 | G8: =E8*F8 -> 0
A9: DA | G9: =E9*F9 -> 0
A10: HRA | G10: =E10*F10 -> 0
A11: Other Allowances | G11: =E11*F11 -> 0
A12: Variable Pay | G12: =E12*F12 -> 0
A13: Bonus | G13: =E13*F13 -> 0
A14: Arrears / Others | G14: =E14*F14 -> 0
A15: Gross Salary | B15: =SUM(B8:B14) -> 30000 | C15: =SUM(C8:C14) -> 30000 | D15: =SUM(D8:D14) -> 30000 | E15: =SUM(E8:E14) -> 0 | G15: =SUM(G8:G14) -> 0
A16: Deductions:
A17: - PF | G17: =E17*F17 -> 0
A18: - Profession Tax | G18: =E18*F18 -> 0
A19: - Income Tax (TDS) | G19: =E19*F19 -> 0
A20: - Loan Deduction | G20: =E20*F20 -> 0
A21: - ESI / Other Deductions | G21: =E21*F21 -> 0
A22: Total Deductions | B22: =SUM(B17:B21) -> 0 | C22: =SUM(C17:C21) -> 0 | D22: =SUM(D17:D21) -> 0 | E22: =SUM(E17:E21) -> 0 | G22: =SUM(G17:G21) -> 0
A23: Net Salary | B23: =B15-B22 -> 30000 | C23: =C15-C22 -> 30000 | D23: =D15-D22 -> 30000 | E23: =E15-E22 -> 0 | G23: =G15-G22 -> 0
A26: Annual Components (if excluded from above) | B26: Latest Year | C26: Previous Year | F26: % to be considered | G26: Eligible Amount (Rs.)
A27: Fixed Bonus | G27: =B27*F27 -> 0
A28: Performance Linked Bonus | G28: =B28*F28 -> 0
A29: LTA | G29: =B29*F29 -> 0
A32: Form 16 Part B Details, if any | G32: Latest Year
A33: Gross Salary as per Form 16
A34: Tax Deducted as per Form 16
A35: Net Salary as per Form 16
A36: Net Salary p.m. (as per Form 16) | G36: =G35/12 -> 0
A39: Salary, Bonus / Incentive, Reimbursement, or other credits from Employer
A41: Month | B41: Date | C41: Amount (Rs.) | D41: Remarks, if any

Sheet Co-app2Salary
A1: Name:
A2: Employer Name:
A3: Designation:
A4: Date of Joining: | B4: 43709 | C4: Total Experience (Years):
B6: Rs.
A7: Component | B7: Latest Month | C7: Previous Month | D7: Previous to previous month | E7: Standard Amount for calculation | F7: % to be considered | G7: Eligible Amount (Rs.)
A8: Basic | G8: =E8*F8 -> 0
A9: DA | G9: =E9*F9 -> 0
A10: HRA | G10: =E10*F10 -> 0
A11: Other Allowances | G11: =E11*F11 -> 0
A12: Variable Pay | G12: =E12*F12 -> 0
A13: Bonus | G13: =E13*F13 -> 0
A14: Arrears / Others | G14: =E14*F14 -> 0
A15: Gross Salary | B15: =SUM(B8:B14) -> 0 | C15: =SUM(C8:C14) -> 0 | D15: =SUM(D8:D14) -> 0 | E15: =SUM(E8:E14) -> 0 | G15: =SUM(G8:G14) -> 0
A16: Deductions:
A17: - PF | G17: =E17*F17 -> 0
A18: - Profession Tax | G18: =E18*F18 -> 0
A19: - Income Tax (TDS) | G19: =E19*F19 -> 0
A20: - Loan Deduction | G20: =E20*F20 -> 0
A21: - ESI / Other Deductions | G21: =E21*F21 -> 0
A22: Total Deductions | B22: =SUM(B17:B21) -> 0 | C22: =SUM(C17:C21) -> 0 | D22: =SUM(D17:D21) -> 0 | E22: =SUM(E17:E21) -> 0 | G22: =SUM(G17:G21) -> 0
A23: Net Salary | B23: =B15-B22 -> 0 | C23: =C15-C22 -> 0 | D23: =D15-D22 -> 0 | E23: =E15-E22 -> 0 | G23: =G15-G22 -> 0
A26: Annual Components (if excluded from above) | B26: Latest Year | C26: Previous Year | F26: % to be considered | G26: Eligible Amount (Rs.)
A27: Fixed Bonus | G27: =B27*F27 -> 0
A28: Performance Linked Bonus | G28: =B28*F28 -> 0
A29: LTA | G29: =B29*F29 -> 0
A32: Form 16 Part B Details, if any | G32: Latest Year
A33: Gross Salary as per Form 16
A34: Tax Deducted as per Form 16
A35: Net Salary as per Form 16
A36: Net Salary p.m. (as per Form 16) | G36: =G35/12 -> 0
A39: Salary, Bonus / Incentive, Reimbursement, or other credits from Employer
A41: Month | B41: Date | C41: Amount (Rs.) | D41: Remarks, if any

Sheet Co-app3Salary
A1: Name:
A2: Employer Name:
A3: Designation:
A4: Date of Joining: | B4: 43709 | C4: Total Experience (Years):
B6: Rs.
A7: Component | B7: Latest Month | C7: Previous Month | D7: Previous to previous month | E7: Standard Amount for calculation | F7: % to be considered | G7: Eligible Amount (Rs.)
A8: Basic | G8: =E8*F8 -> 0
A9: DA | G9: =E9*F9 -> 0
A10: HRA | G10: =E10*F10 -> 0
A11: Other Allowances | G11: =E11*F11 -> 0
A12: Variable Pay | G12: =E12*F12 -> 0
A13: Bonus | G13: =E13*F13 -> 0
A14: Arrears / Others | G14: =E14*F14 -> 0
A15: Gross Salary | B15: =SUM(B8:B14) -> 0 | C15: =SUM(C8:C14) -> 0 | D15: =SUM(D8:D14) -> 0 | E15: =SUM(E8:E14) -> 0 | G15: =SUM(G8:G14) -> 0
A16: Deductions:
A17: - PF | G17: =E17*F17 -> 0
A18: - Profession Tax | G18: =E18*F18 -> 0
A19: - Income Tax (TDS) | G19: =E19*F19 -> 0
A20: - Loan Deduction | G20: =E20*F20 -> 0
A21: - ESI / Other Deductions | G21: =E21*F21 -> 0
A22: Total Deductions | B22: =SUM(B17:B21) -> 0 | C22: =SUM(C17:C21) -> 0 | D22: =SUM(D17:D21) -> 0 | E22: =SUM(E17:E21) -> 0 | G22: =SUM(G17:G21) -> 0
A23: Net Salary | B23: =B15-B22 -> 0 | C23: =C15-C22 -> 0 | D23: =D15-D22 -> 0 | E23: =E15-E22 -> 0 | G23: =G15-G22 -> 0
A26: Annual Components (if excluded from above) | B26: Latest Year | C26: Previous Year | F26: % to be considered | G26: Eligible Amount (Rs.)
A27: Fixed Bonus | G27: =B27*F27 -> 0
A28: Performance Linked Bonus | G28: =B28*F28 -> 0
A29: LTA | G29: =B29*F29 -> 0
A32: Form 16 Part B Details, if any | G32: Latest Year
A33: Gross Salary as per Form 16
A34: Tax Deducted as per Form 16
A35: Net Salary as per Form 16
A36: Net Salary p.m. (as per Form 16) | G36: =G35/12 -> 0
A39: Salary, Bonus / Incentive, Reimbursement, or other credits from Employer
A41: Month | B41: Date | C41: Amount (Rs.) | D41: Remarks, if any

Sheet A3SP&L
A1: Parameter Code | B1: Parameter_Desc | C1: =E1-2 -> 2021 | D1: =E1-1 -> 2022 | E1: =IF(BasicInput!C1="Prime",IF(Prime1!B7="",2020,Prime1!B7),IF(Afford1!B7="",2020,Afford1!B7)) -> 2023 | F1: =E1+1 -> 2024 | G1: =E1+2 -> 2025
A2: GRDOMSAL | B2: Gross Domestic Sales | C2: =IF(BasicInput!$C$1="Prime",PrimeConsolidated!E8,AffordConsolidated!E9)*100000+'44AD,44ADA,44AEIncome'!D116 -> 1470800 | D2: =IF(BasicInput!$C$1="Prime",PrimeConsolidated!D8,AffordConsolidated!D9)*100000+'44AD,44ADA,44AEIncome'!C116 -> 1571200 | E2: =IF(BasicInput!$C$1="Prime",PrimeConsolidated!C8,AffordConsolidated!C9)*100000+'44AD,44ADA,44AEIncome'!B116 -> 1698700 | F2: 0 | G2: 0
A3: EXPSAL | B3: Export Sales | C3: =PrimeConsolidated!E9*100000 -> 0 | D3: =PrimeConsolidated!D9*100000 -> 0 | E3: =PrimeConsolidated!C9*100000 -> 0 | F3: 0 | G3: 0
A4: LESEXCDUT | B4: LESS: Excise duty | C4: =AffordConsolidated!E10*100000 -> 0 | D4: =AffordConsolidated!D10*100000 -> 0 | E4: =AffordConsolidated!C10*100000 -> 0 | F4: 0 | G4: 0
A5: TRDOPRINC | B5: ADD: Trading / Other Operating Income | C5: =IF(BasicInput!$C$1="Prime",SUM(PrimeConsolidated!E10:E19),AffordConsolidated!E12)*100000 -> 0 | D5: =IF(BasicInput!$C$1="Prime",SUM(PrimeConsolidated!D10:D19),AffordConsolidated!D12)*100000 -> 0 | E5: =IF(BasicInput!$C$1="Prime",SUM(PrimeConsolidated!C10:C19),AffordConsolidated!C12)*100000 -> 0 | F5: 0 | G5: 0
A6: EXPINC | B6: Export Incentives | C6: 0 | D6: 0 | E6: 0 | F6: 0 | G6: 0
A7: DUDRAW | B7: Duty Drawback | C7: 0 | D7: 0 | E7: 0 | F7: 0 | G7: 0
A8: OTHER | B8: Others | C8: 0 | D8: 0 | E8: 0 | F8: 0 | G8: 0
A9: IMPORTD | B9: Imported | C9: 0 | D9: 0 | E9: 0 | F9: 0 | G9: 0
A10: INDIGENOUS | B10: Indigenous | C10: 0 | D10: 0 | E10: 0 | F10: 0 | G10: 0
A11: IMPORTED_1 | B11: Imported | C11: 0 | D11: 0 | E11: 0 | F11: 0 | G11: 0
A12: INDIGENOS1 | B12: Indigenous | C12: 0 | D12: 0 | E12: 0 | F12: 0 | G12: 0
A13: POWFUEL | B13: POWER & FUEL | C13: 0 | D13: 0 | E13: 0 | F13: 0 | G13: 0
A14: DIRLABOUR | B14: DIRECT LABOUR | C14: =PrimeConsolidated!E28*100000 -> 0 | D14: =PrimeConsolidated!D28*100000 -> 0 | E14: =PrimeConsolidated!C28*100000 -> 0 | F14: 0 | G14: 0
A15: OTHMANEXP | B15: OTHER MANUFACTURING EXPENSES | C15: =IF(BasicInput!$C$1="Prime",PrimeConsolidated!E25,AffordConsolidated!E16)*100000 -> 0 | D15: =IF(BasicInput!$C$1="Prime",PrimeConsolidated!D25,AffordConsolidated!D16)*100000 -> 0 | E15: =IF(BasicInput!$C$1="Prime",PrimeConsolidated!C25,AffordConsolidated!C16)*100000 -> 0 | F15: 0 | G15: 0
A16: DEPRECIA | B16: DEPRECIATION | C16: =IF(BasicInput!$C$1="Prime",PrimeConsolidated!E32,AffordConsolidated!E23)*100000 -> 0 | D16: =IF(BasicInput!$C$1="Prime",PrimeConsolidated!D32,AffordConsolidated!D23)*100000 -> 0 | E16: =IF(BasicInput!$C$1="Prime",PrimeConsolidated!C32,AffordConsolidated!C23)*100000 -> 0 | F16: 0 | G16: 0
A17: REPMAINT | B17: REPAIRS & MAINTENANCE | C17: 0 | D17: 0 | E17: 0 | F17: 0 | G17: 0
A18: COSTTRDGDS | B18: COST OF TRADING GOODS | C18: =IF(BasicInput!$C$1="Prime",PrimeConsolidated!E21,AffordConsolidated!E15)*100000 -> 0 | D18: =IF(BasicInput!$C$1="Prime",PrimeConsolidated!D21,AffordConsolidated!D15)*100000 -> 0 | E18: =IF(BasicInput!$C$1="Prime",PrimeConsolidated!C21,AffordConsolidated!C15)*100000 -> 0 | F18: 0 | G18: 0
A19: ADOPSTKPRC | B19: ADD: OPENING STOCK IN PROCESS | C19: 0 | D19: 0 | E19: 0 | F19: 0 | G19: 0
A20: DEDCLSTKPR | B20: DEDUCT: CLOSING STOCK IN PROCESS | C20: 0 | D20: 0 | E20: 0 | F20: 0 | G20: 0
A21: ADDOPFIGD | B21: ADD: OPENING STOCK OF FINISHED GOODS | C21: 0 | D21: 0 | E21: 0 | F21: 0 | G21: 0
A22: DEDCLSTFIG | B22: DEDUCT: CLOSING STOCK OF FINISHED GOODS | C22: 0 | D22: 0 | E22: 0 | F22: 0 | G22: 0
A23: SGADMEXP | B23: SELLING, GENERAL & ADM EXPENSES | C23: =IF(BasicInput!$C$1="Prime",SUM(PrimeConsolidated!E29:E30),AffordConsolidated!E19)*100000+'44AD,44ADA,44AEIncome'!D120 -> 1029560 | D23: =IF(BasicInput!$C$1="Prime",SUM(PrimeConsolidated!D29:D30),AffordConsolidated!D19)*100000+'44AD,44ADA,44AEIncome'!C120 -> 1099840 | E23: =IF(BasicInput!$C$1="Prime",SUM(PrimeConsolidated!C29:C30),AffordConsolidated!C19)*100000+'44AD,44ADA,44AEIncome'!B120 -> 1216140 | F23: 0 | G23: 0
A24: INTWC | B24: Interest - WC | C24: =PrimeConsolidated!E37*100000 -> 0 | D24: =PrimeConsolidated!D37*100000 -> 0 | E24: =PrimeConsolidated!C37*100000 -> 0 | F24: 0 | G24: 0
A25: INTTRMLN | B25: Interest - Term Loans | C25: =IF(BasicInput!$C$1="Prime",PrimeConsolidated!E38,AffordConsolidated!E25)*100000 -> 0 | D25: =IF(BasicInput!$C$1="Prime",PrimeConsolidated!D38,AffordConsolidated!D25)*100000 -> 0 | E25: =IF(BasicInput!$C$1="Prime",PrimeConsolidated!C38,AffordConsolidated!C25)*100000 -> 0 | F25: 0 | G25: 0
A26: INTEWC1 | B26: Interest - WC | C26: 0 | D26: 0 | E26: 0 | F26: 0 | G26: 0
A27: INTETRMLN1 | B27: Interest - Term Loans | C27: =PrimeConsolidated!E40*100000 -> 0 | D27: =PrimeConsolidated!D40*100000 -> 0 | E27: =PrimeConsolidated!C40*100000 -> 0 | F27: 0 | G27: 0
A28: BNKCHG | B28: Bank Charges | C28: 0 | D28: 0 | E28: 0 | F28: 0 | G28: 0
A29: INTDEPDIV | B29: (I) Interest On Deposits & Dividend Received | C29: 0 | D29: 0 | E29: 0 | F29: 0 | G29: 0
A30: FORXGAIN | B30: (II) Forex Gains | C30: 0 | D30: 0 | E30: 0 | F30: 0 | G30: 0
A31: NOOPINCSB | B31: (III) Non Operating Income from Subsidiaries | C31: 0 | D31: 0 | E31: 0 | F31: 0 | G31: 0
A32: TXRFND | B32: (IV) Tax Refund | C32: 0 | D32: 0 | E32: 0 | F32: 0 | G32: 0
A33: MISCINC | B33: (V) Misc Income | C33: 0 | D33: 0 | E33: 0 | F33: 0 | G33: 0
A34: PFSALASINV | B34: (VI) Profit on sale of assets & Investments | C34: 0 | D34: 0 | E34: 0 | F34: 0 | G34: 0
A35: OTHINC1 | B35: Other Income | C35: =IF(BasicInput!$C$1="Prime",PrimeConsolidated!E27,AffordConsolidated!E27)*100000 -> 0 | D35: =IF(BasicInput!$C$1="Prime",PrimeConsolidated!D27,AffordConsolidated!D27)*100000 -> 0 | E35: =IF(BasicInput!$C$1="Prime",PrimeConsolidated!C27,AffordConsolidated!C27)*100000 -> 0 | F35: 0 | G35: 0
A36: PRVEXPWRT | B36: (I) Provisions / Expenses Written Back | C36: 0 | D36: 0 | E36: 0 | F36: 0 | G36: 0
A37: LOSSALINV | B37: (I) Loss on sale of Investments | C37: 0 | D37: 0 | E37: 0 | F37: 0 | G37: 0
A38: LOSSALFA | B38: (II) Loss on sale of FA | C38: 0 | D38: 0 | E38: 0 | F38: 0 | G38: 0
A39: DERLOSBKD | B39: (III) Derivative Losses booked | C39: 0 | D39: 0 | E39: 0 | F39: 0 | G39: 0
A40: PREXPWRTOF | B40: (I) Preli.Exp / One Time Expenses Written Off | C40: =PrimeConsolidated!E34*100000 -> 0 | D40: =PrimeConsolidated!D34*100000 -> 0 | E40: =PrimeConsolidated!C34*100000 -> 0 | F40: 0 | G40: 0
...

Sheet A3SBalSheet
A1: Parameter Code | B1: Parameter_Desc | C1: =E1-2 -> 2021 | D1: =E1-1 -> 2022 | E1: =IF(BasicInput!C1="Prime",IF(Prime1!B7="",2020,Prime1!B7),IF(Afford1!B7="",2020,Afford1!B7)) -> 2023 | F1: =E1+1 -> 2024 | G1: =E1+2 -> 2025
A2: SHTRMBORAB | B2: (i)Short term Borrowings from applicant bank (CC / WCDL) | C2: =IF(BasicInput!C1="Prime",PrimeConsolidated!E86,AffordConsolidated!E58)*100000 -> 0 | D2: =IF(BasicInput!C1="Prime",PrimeConsolidated!D86,AffordConsolidated!D58)*100000 -> 0 | E2: =IF(BasicInput!C1="Prime",PrimeConsolidated!C86,AffordConsolidated!C58)*100000 -> 0 | F2: 0 | G2: 0
A3: SHTRMBOROB | B3: (ii)Short term Borrowingsfrom other banks | C3: =PrimeConsolidated!E87*100000 -> 0 | D3: =PrimeConsolidated!D87*100000 -> 0 | E3: =PrimeConsolidated!C87*100000 -> 0 | F3: 0 | G3: 0
A4: SHTRMBOR12 | B4: Short term Borrowings(of (i) and (ii) in which Bill purchased & disc.) | C4: 0 | D4: 0 | E4: 0 | F4: 0 | G4: 0
A5: SUNDRYCRD | B5: Sundry Creditors (Trade) | C5: =IF(BasicInput!C1="Prime",PrimeConsolidated!E80,AffordConsolidated!E57)*100000 -> 0 | D5: =IF(BasicInput!C1="Prime",PrimeConsolidated!D80,AffordConsolidated!D57)*100000 -> 0 | E5: =IF(BasicInput!C1="Prime",PrimeConsolidated!C80,AffordConsolidated!C57)*100000 -> 0 | F5: 0 | G5: 0
A6: SHTRMBORAG | B6: Short term borrowings from Associates & Group Concerns | C6: =AffordConsolidated!E56*100000 -> 0 | D6: =AffordConsolidated!D56*100000 -> 0 | E6: =AffordConsolidated!C56*100000 -> 0 | F6: 0 | G6: 0
A7: SHTRMBORCP | B7: Short Term borrowings / Commercial Paper | C7: 0 | D7: 0 | E7: 0 | F7: 0 | G7: 0
A8: SHTRMBORO | B8: Short term borrowings from Others | C8: =PrimeConsolidated!E88*100000 -> 0 | D8: =PrimeConsolidated!D88*100000 -> 0 | E8: =PrimeConsolidated!C88*100000 -> 0 | F8: 0 | G8: 0
A9: ADVPCDPDL | B9: Advances/ payments from customers/deposits from dealers. | C9: =PrimeConsolidated!E81*100000 -> 0 | D9: =PrimeConsolidated!D81*100000 -> 0 | E9: =PrimeConsolidated!C81*100000 -> 0 | F9: 0 | G9: 0
A10: PRVFORTAX | B10: Provision for taxation | C10: 0 | D10: 0 | E10: 0 | F10: 0 | G10: 0
A11: PROPDVD | B11: Proposed dividend | C11: 0 | D11: 0 | E11: 0 | F11: 0 | G11: 0
A12: OTHSTALIAB | B12: Other Statutory Liabilities( Due within One Year) | C12: 0 | D12: 0 | E12: 0 | F12: 0 | G12: 0
A13: INSTTRMLNS | B13: Installments of Term loans / Debentures / DPGs etc. (due within 1 year) | C13: =AffordConsolidated!E51 -> 0 | D13: =AffordConsolidated!D51 -> 0 | E13: =AffordConsolidated!C51 -> 0 | F13: 0 | G13: 0
A14: DEPDUEREP | B14: Deposits due for repayment (due within 1 year) | C14: 0 | D14: 0 | E14: 0 | F14: 0 | G14: 0
A15: PREFSHAR | B15: Preference Shares redeemable (within 1 year) | C15: 0 | D15: 0 | E15: 0 | F15: 0 | G15: 0
A16: OTHCURLIA1 | B16: Other Current liabilities & provisions (due within 1 year) | C16: =IF(BasicInput!C1="Prime",PrimeConsolidated!E83,AffordConsolidated!E59)*100000 -> 0 | D16: =IF(BasicInput!C1="Prime",PrimeConsolidated!D83,AffordConsolidated!D59)*100000 -> 0 | E16: =IF(BasicInput!C1="Prime",PrimeConsolidated!C83,AffordConsolidated!C59)*100000 -> 0 | F16: 0 | G16: 0
A17: INTACCNTDU | B17: Interest acc but not due | C17: 0 | D17: 0 | E17: 0 | F17: 0 | G17: 0
A18: PRVNPA | B18: Provision for NPA | C18: 0 | D18: 0 | E18: 0 | F18: 0 | G18: 0
A19: PRVENCASHGT | B19: Provision for leave encashment & gratuity | C19: 0 | D19: 0 | E19: 0 | F19: 0 | G19: 0
A20: UNCLMDVD | B20: Unclaimed dividend | C20: 0 | D20: 0 | E20: 0 | F20: 0 | G20: 0
A21: OTHLIAB | B21: Other Liabilities | C21: =IF(BasicInput!C1="Prime",PrimeConsolidated!E82,AffordConsolidated!E60)*100000 -> 0 | D21: =IF(BasicInput!C1="Prime",PrimeConsolidated!D82,AffordConsolidated!D60)*100000 -> 0 | E21: =IF(BasicInput!C1="Prime",PrimeConsolidated!C82,AffordConsolidated!C60)*100000 -> 0 | F21: 0 | G21: 0
A22: DUESUBAFF | B22: Due to Subsidiary companies/ affiliates | C22: 0 | D22: 0 | E22: 0 | F22: 0 | G22: 0
A23: TAXINTDVDP | B23: Tax on Interim Dividend Payable | C23: 0 | D23: 0 | E23: 0 | F23: 0 | G23: 0
A24: WTCL | B24: WCTL | C24: 0 | D24: 0 | E24: 0 | F24: 0 | G24: 0
A25: PREFSHR1 | B25: Pref. Shares (portion redeemable after 1 Yr) | C25: 0 | D25: 0 | E25: 0 | F25: 0 | G25: 0
A26: TRMLNEX1 | B26: Term Loans (Excluding installments payable within one year) | C26: =AffordConsolidated!E52 -> 0 | D26: =AffordConsolidated!D52 -> 0 | E26: =AffordConsolidated!C52 -> 0 | F26: 0 | G26: 0
A27: TRMLNFIS | B27: Term Loans - From Fis | C27: =IF(BasicInput!C1="Prime",PrimeConsolidated!E60,AffordConsolidated!E53)*100000 -> 0 | D27: =IF(BasicInput!C1="Prime",PrimeConsolidated!D60,AffordConsolidated!D53)*100000 -> 0 | E27: =IF(BasicInput!C1="Prime",PrimeConsolidated!C60,AffordConsolidated!C53)*100000 -> 0 | F27: 0 | G27: 0
A28: DEBENTRS | B28: Debentures | C28: 0 | D28: 0 | E28: 0 | F28: 0 | G28: 0
A29: TERMDEP | B29: Term deposits | C29: 0 | D29: 0 | E29: 0 | F29: 0 | G29: 0
A30: UNSECLNS | B30: Unsecured loans | C30: =PrimeConsolidated!E61*100000 -> 0 | D30: =PrimeConsolidated!D61*100000 -> 0 | E30: =PrimeConsolidated!C61*100000 -> 0 | F30: 0 | G30: 0
A31: BORSSUBAFI | B31: Borrowings from subsidiaries / affiliates (Quasi Equity) | C31: =IF(BasicInput!C1="Prime",PrimeConsolidated!E57,AffordConsolidated!E50+AffordConsolidated!E42)*100000 -> 0 | D31: =IF(BasicInput!C1="Prime",PrimeConsolidated!D57,AffordConsolidated!D50+AffordConsolidated!D42)*100000 -> 0 | E31: =IF(BasicInput!C1="Prime",PrimeConsolidated!C57,AffordConsolidated!C50+AffordConsolidated!C42)*100000 -> 0 | F31: 0 | G31: 0
A32: DEPDEALERS | B32: Deposit from Dealers (only if considered as available for long term) | C32: 0 | D32: 0 | E32: 0 | F32: 0 | G32: 0
A33: OTHTRMLIA | B33: Other term liabilities | C33: 0 | D33: 0 | E33: 0 | F33: 0 | G33: 0
A34: DEFRTXLIA | B34: Deferred Tax Liability | C34: 0 | D34: 0 | E34: 0 | F34: 0 | G34: 0
A35: INTCORPLN | B35: Inter Corporate Loan | C35: 0 | D35: 0 | E35: 0 | F35: 0 | G35: 0
A36: OTHLNADV | B36: Other Loan & Advances | C36: 0 | D36: 0 | E36: 0 | F36: 0 | G36: 0
A37: PRPROCAP | B37: Partners capital / Proprietors capital | C37: =PrimeConsolidated!E53*100000 -> 0 | D37: =PrimeConsolidated!D53*100000 -> 0 | E37: =PrimeConsolidated!C53*100000 -> 0 | F37: 0 | G37: 0
A38: SHARECAP | B38: Share Capital (Paid-up) | C38: =IF(BasicInput!C1="Prime",PrimeConsolidated!E52,AffordConsolidated!E41)*100000 -> 0 | D38: =IF(BasicInput!C1="Prime",PrimeConsolidated!D52,AffordConsolidated!D41)*100000 -> 0 | E38: =IF(BasicInput!C1="Prime",PrimeConsolidated!C52,AffordConsolidated!C41)*100000 -> 0 | F38: 0 | G38: 0
A39: SHAREAPP | B39: Share Application (finalized for allotment) | C39: 0 | D39: 0 | E39: 0 | F39: 0 | G39: 0
A40: SACR | B40: Statutory and Capital Reserves | C40: 0 | D40: 0 | E40: 0 | F40: 0 | G40: 0
...

Sheet 44AD,44ADA,44AEIncome
A1: Assessee Name: | B1: SONA NAVANI
A2: PAN: | B2: ATIPN6970B
A4: Particulars | B4: Assessment Year
B5: 2023-24 | C5: 2022-23 | D5: 2021-22
A6: ITR Acknowledgment No. | B6: 205512330250823 | C6: 967727770240722 | D6: 769762270311021
A7: ITR Acknowledgment Date | B7: 45163 | C7: 44766 | D7: 44500
A8: Gross Turnover / Receipts u/s 44AD (Rs.) | B8: 1698700 | C8: 1571200 | D8: 1470800
A9: Net Profit (Earnings) reported u/s 44AD (Rs.) | B9: 482560 | C9: 471360 | D9: 441240
A10: Gross Receipts u/s 44ADA (Rs.)
A11: Net Profit (Earnings) reported u/s 44ADA (Rs.)
A12: Gross Receipts u/s 44AE (Rs.)
A13: Net Profit (Earnings) reported u/s 44AE (Rs.)
A14: Total Gross Turnover / Receipts (Rs.) | B14: =B8+B10+B12 -> 1698700 | C14: =C8+C10+C12 -> 1571200 | D14: =D8+D10+D12 -> 1470800
A15: Total Net Income (Rs.) | B15: =B9+B11+B13 -> 482560 | C15: =C9+C11+C13 -> 471360 | D15: =D9+D11+D13 -> 441240
A16: Tax Paid (Rs.)
A17: PAT (Rs.) | B17: =B15-B16 -> 482560 | C17: =C15-C16 -> 471360 | D17: =D15-D16 -> 441240
A22: Assessee Name:
A23: PAN:
A25: Particulars | B25: Assessment Year
B26: 2020-21 | C26: 2019-20 | D26: 2018-19
A27: ITR Acknowledgment No.
A28: ITR Acknowledgment Date
A29: Gross Turnover / Receipts u/s 44AD (Rs.)
A30: Net Profit (Earnings) reported u/s 44AD (Rs.)
A31: Gross Receipts u/s 44ADA (Rs.)
A32: Net Profit (Earnings) reported u/s 44ADA (Rs.)
A33: Gross Receipts u/s 44AE (Rs.)
A34: Net Profit (Earnings) reported u/s 44AE (Rs.)
A35: Total Gross Turnover / Receipts (Rs.) | B35: =B29+B31+B33 -> 0 | C35: =C29+C31+C33 -> 0 | D35: =D29+D31+D33 -> 0
A36: Total Net Income (Rs.) | B36: =B30+B32+B34 -> 0 | C36: =C30+C32+C34 -> 0 | D36: =D30+D32+D34 -> 0
A37: Tax Paid (Rs.)
A38: PAT (Rs.) | B38: =B36-B37 -> 0 | C38: =C36-C37 -> 0 | D38: =D36-D37 -> 0
A43: Assessee Name:
A44: PAN:
A46: Particulars | B46: Assessment Year
B47: 2020-21 | C47: 2019-20 | D47: 2018-19
A48: ITR Acknowledgment No.
A49: ITR Acknowledgment Date
A50: Gross Turnover / Receipts u/s 44AD (Rs.)
A51: Net Profit (Earnings) reported u/s 44AD (Rs.)
...

Sheet 26ASMapping
A1: Customer / Entity Name:
A2: Financial Year:
A4: S. No. | B4: Party Name | C4: Payment under Section | D4: Amount Credited (Rs.) | E4: Tax Deducted (Rs.)
A5: 1
A6: 2
A7: 3
A8: 4
A9: 5
A10: 6
A11: 7
A12: 8
A13: 9
A14: 10
A15: 11
A16: 12
... A54: 50
A55: Total | D55: =SUM(D27:D54) -> 0 | E55: =SUM(E27:E54) -> 0

Sheet GSTSummary
A1: Name of Entity | B1: GSTIN | C1: Financial Year | D1: Business Location | E1: Month | F1: Outward Taxable Supply (Rs.)
E2: April
E3: May
E4: June
E5: July
E6: August
E7: September
E8: October
E9: November
E10: December
E11: January
E12: February
E13: March
A14: TOTAL VALUE OF OUTWARD TAXABLE SUPPLY | F14: =SUM(F2:F13) -> 0

Sheet ExistingLoans&Facilities&RTR
A1: S. No. | B1: Bank / FI Name | C1: Loan / Facility Type (Select from Dropdown) | D1: Loan / Facility Amount (Rs.) | E1: Current Outstanding (Rs.) | F1: Start Date | G1: Tenure (Months) | H1: In case closed, Closure Date | I1: MOB | J1: Borrower name for loan / facility | K1: Loan / Facility A/c No. | L1: Repayment Bank details | M1: Status (Select from Dropdown) | N1: Running EMI (Rs.) | O1: % of EMI to be considered | P1: EMI Amount to be considered (Rs.) | Q1: Remarks | R1: Month-on-month RTR (upto last 12 months) -->
R2: =IF('Banking - Non PDF'!$A$27="","",'Banking - Non PDF'!$A$27) -> 45139 | S2: =IF('Banking - Non PDF'!$A$28="","",'Banking - Non PDF'!$A$28) -> 45170 | T2: =IF('Banking - Non PDF'!$A$29="","",'Banking - Non PDF'!$A$29) -> 45200 | U2: =IF('Banking - Non PDF'!$A$30="","",'Banking - Non PDF'!$A$30) -> 45231 | V2: =IF('Banking - Non PDF'!$A$31="","",'Banking - Non PDF'!$A$31) -> 45261 | W2: =IF('Banking - Non PDF'!$A$32="","",'Banking - Non PDF'!$A$32) -> 45292 | X2: =IF('Banking - Non PDF'!$A$33="","",'Banking - Non PDF'!$A$33) | Y2: =IF('Banking - Non PDF'!$A$34="","",'Banking - Non PDF'!$A$34) | Z2: =IF('Banking - Non PDF'!$A$35="","",'Banking - Non PDF'!$A$35) | AA2: =IF('Banking - Non PDF'!$A$36="","",'Banking - Non PDF'!$A$36) | AB2: =IF('Banking - Non PDF'!$A$37="","",'Banking - Non PDF'!$A$37) | AC2: =IF('Banking - Non PDF'!$A$38="","",'Banking - Non PDF'!$A$38)
A3: 1 | B3: No Active Loan | I3: =IF(F3="","",IF(H3<>"",DATEDIF(F3,H3,"M"),DATEDIF(F3,TODAY(),"M"))) | P3: =IF(OR(M3="",M3="Active"),N3*IF(O3="",100%,O3),0) -> 0
A4: 2 | I4: =IF(F4="","",IF(H4<>"",DATEDIF(F4,H4,"M"),DATEDIF(F4,TODAY(),"M"))) | P4: =IF(OR(M4="",M4="Active"),N4*IF(O4="",100%,O4),0) -> 0
A5: 3 | I5: =IF(F5="","",IF(H5<>"",DATEDIF(F5,H5,"M"),DATEDIF(F5,TODAY(),"M"))) | P5: =IF(OR(M5="",M5="Active"),N5*IF(O5="",100%,O5),0) -> 0
A6: 4 | I6: =IF(F6="","",IF(H6<>"",DATEDIF(F6,H6,"M"),DATEDIF(F6,TODAY(),"M"))) | P6: =IF(OR(M6="",M6="Active"),N6*IF(O6="",100%,O6),0) -> 0
A7: 5 | I7: =IF(F7="","",IF(H7<>"",DATEDIF(F7,H7,"M"),DATEDIF(F7,TODAY(),"M"))) | P7: =IF(OR(M7="",M7="Active"),N7*IF(O7="",100%,O7),0) -> 0
A8: 6 | I8: =IF(F8="","",IF(H8<>"",DATEDIF(F8,H8,"M"),DATEDIF(F8,TODAY(),"M"))) | P8: =IF(OR(M8="",M8="Active"),N8*IF(O8="",100%,O8),0) -> 0
A9: 7 | I9: =IF(F9="","",IF(H9<>"",DATEDIF(F9,H9,"M"),DATEDIF(F9,TODAY(),"M"))) | P9: =IF(OR(M9="",M9="Active"),N9*IF(O9="",100%,O9),0) -> 0
A10: 8 | I10: =IF(F10="","",IF(H10<>"",DATEDIF(F10,H10,"M"),DATEDIF(F10,TODAY(),"M"))) | P10: =IF(OR(M10="",M10="Active"),N10*IF(O10="",100%,O10),0) -> 0
A11: 9 | I11: =IF(F11="","",IF(H11<>"",DATEDIF(F11,H11,"M"),DATEDIF(F11,TODAY(),"M"))) | P11: =IF(OR(M11="",M11="Active"),N11*IF(O11="",100%,O11),0) -> 0
A12: 10 | I12: =IF(F12="","",IF(H12<>"",DATEDIF(F12,H12,"M"),DATEDIF(F12,TODAY(),"M"))) | P12: =IF(OR(M12="",M12="Active"),N12*IF(O12="",100%,O12),0) -> 0
A13: 11 | I13: =IF(F13="","",IF(H13<>"",DATEDIF(F13,H13,"M"),DATEDIF(F13,TODAY(),"M"))) | P13: =IF(OR(M13="",M13="Active"),N13*IF(O13="",100%,O13),0) -> 0
A14: 12 | I14: =IF(F14="","",IF(H14<>"",DATEDIF(F14,H14,"M"),DATEDIF(F14,TODAY(),"M"))) | P14: =IF(OR(M14="",M14="Active"),N14*IF(O14="",100%,O14),0) -> 0
A15: 13 | I15: =IF(F15="","",IF(H15<>"",DATEDIF(F15,H15,"M"),DATEDIF(F15,TODAY(),"M"))) | P15: =IF(OR(M15="",M15="Active"),N15*IF(O15="",100%,O15),0) -> 0
... A102: 100 | I102: =IF(F102="","",IF(H102<>"",DATEDIF(F102,H102,"M"),DATEDIF(F102,TODAY(),"M"))) | P102: =IF(OR(M102="",M102="Active"),N102*IF(O102="",100%,O102),0) -> 0
L103: Obligation to be considered | N103: =SUM(P3:P102) -> 0
L104: Total Obligations | N104: =SUM(N3:N102) -> 0
L105: Obligations not considered | N105: =N104-N103 -> 0

Sheet Banking - Non PDF
A1: Name of Customer | C1: =IF(PrimeConsolidated!B3="","",CONCATENATE(PrimeConsolidated!B3," (Consolidated Banking in Rs. Lacs)")) -> SONA NAVANI & Group (Consolidated Banking in Rs. Lacs)
A2: Name of Customer | B2: Balance / Utilization on date (Rs. Lacs) | E2: Min Balance of the month (Rs. Lacs) | F2: Max Balance of the month (Rs. Lacs) | G2: Average (Rs. Lacs) | H2: Total Inflows (Rs. Lacs) | I2: Total Outflows (Rs. Lacs) | J2: Loan Disbursal incl in Inflows (Rs. Lacs) | K2: Interest (debited) / credited (Rs. Lacs) | L2: Intra Group transaction value included (Rs. Lacs) | N2: Cash Entry Value (Rs. Lacs) | P2: Net Flow (Rs. Lacs) | Q2: No. of I/W Return | R2: No. of O/W Return | S2: No. of Credit Entries | T2: No. of Debit Entries | U2: Net Inflows (Rs. Lacs) | V2: Net Outflows (Rs. Lacs)
B3: 10 | C3: 20 | D3: 30 | L3: Debit | M3: Credit | N3: Debit | O3: Credit
A4: =IF($A$27="","",$A$27) -> 45139 | B4: =(B27+B50+B73+B96+B119+B142+B165+B188+B211+B234+B257+B280+B303+B326+B349+B372+B395+B418+B441+B464)/100000 -> 0 | C4: =(C27+C50+C73+C96+C119+C142+C165+C188+C211+C234+C257+C280+C303+C326+C349+C372+C395+C418+C441+C464)/100000 -> 0 | D4: =(D27+D50+D73+D96+D119+D142+D165+D188+D211+D234+D257+D280+D303+D326+D349+D372+D395+D418+D441+D464)/100000 -> 0 | E4: =(E27+E50+E73+E96+E119+E142+E165+E188+E211+E234+E257+E280+E303+E326+E349+E372+E395+E418+E441+E464)/100000 -> 0 | F4: =(F27+F50+F73+F96+F119+F142+F165+F188+F211+F234+F257+F280+F303+F326+F349+F372+F395+F418+F441+F464)/100000 -> 0 | G4: =AVERAGE(B4:D4) -> 0 | H4: =(H27+H50+H73+H96+H119+H142+H165+H188+H211+H234+H257+H280+H303+H326+H349+H372+H395+H418+H441+H464)/100000 -> 0.0065 | I4: =(I27+I50+I73+I96+I119+I142+I165+I188+I211+I234+I257+I280+I303+I326+I349+I372+I395+I418+I441+I464)/100000 -> 0.0065 | J4: =(J27+J50+J73+J96+J119+J142+J165+J188+J211+J234+J257+J280+J303+J326+J349+J372+J395+J418+J441+J464)/100000 -> 0 | K4: =(K27+K50+K73+K96+K119+K142+K165+K188+K211+K234+K257+K280+K303+K326+K349+K372+K395+K418+K441+K464)/100000 -> 0 | L4: =(L27+L50+L73+L96+L119+L142+L165+L188+L211+L234+L257+L280+L303+L326+L349+L372+L395+L418+L441+L464)/100000 -> 0 | M4: =(M27+M50+M73+M96+M119+M142+M165+M188+M211+M234+M257+M280+M303+M326+M349+M372+M395+M418+M441+M464)/100000 -> 0 | N4: =(N27+N50+N73+N96+N119+N142+N165+N188+N211+N234+N257+N280+N303+N326+N349+N372+N395+N418+N441+N464)/100000 -> 0 | O4: =(O27+O50+O73+O96+O119+O142+O165+O188+O211+O234+O257+O280+O303+O326+O349+O372+O395+O418+O441+O464)/100000 -> 0 | P4: =(P27+P50+P73+P96+P119+P142+P165+P188+P211+P234+P257+P280+P303+P326+P349+P372+P395+P418+P441+P464)/100000 -> 0 | Q4: =(Q27+Q50+Q73+Q96+Q119+Q142+Q165+Q188+Q211+Q234+Q257+Q280+Q303+Q326+Q349+Q372+Q395+Q418+Q441+Q464) -> 0 | R4: =(R27+R50+R73+R96+R119+R142+R165+R188+R211+R234+R257+R280+R303+R326+R349+R372+R395+R418+R441+R464) -> 0 | S4: =(S27+S50+S73+S96+S119+S142+S165+S188+S211+S234+S257+S280+S303+S326+S349+S372+S395+S418+S441+S464) -> 0 | T4: =(T27+T50+T73+T96+T119+T142+T165+T188+T211+T234+T257+T280+T303+T326+T349+T372+T395+T418+T441+T464) -> 0 | U4: =(U27+U50+U73+U96+U119+U142+U165+U188+U211+U234+U257+U280+U303+U326+U349+U372+U395+U418+U441+U464)/100000 -> 0.0065 | V4: =(V27+V50+V73+V96+V119+V142+V165+V188+V211+V234+V257+V280+V303+V326+V349+V372+V395+V418+V441+V464)/100000 -> 0.0065
A5: =IF($A$28="","",$A$28) -> 45170 | B5: =(B28+B51+B74+B97+B120+B143+B166+B189+B212+B235+B258+B281+B304+B327+B350+B373+B396+B419+B442+B465)/100000 -> 0.9799996 | C5: =(C28+C51+C74+C97+C120+C143+C166+C189+C212+C235+C258+C281+C304+C327+C350+C373+C396+C419+C442+C465)/100000 -> 0.0149996 | D5: =(D28+D51+D74+D97+D120+D143+D166+D189+D212+D235+D258+D281+D304+D327+D350+D373+D396+D419+D442+D465)/100000 -> 0.0229996 | E5: =(E28+E51+E74+E97+E120+E143+E166+E189+E212+E235+E258+E281+E304+E327+E350+E373+E396+E419+E442+E465)/100000 -> 0 | F5: =(F28+F51+F74+F97+F120+F143+F166+F189+F212+F235+F258+F281+F304+F327+F350+F373+F396+F419+F442+F465)/100000 -> 1.0149996 | G5: =AVERAGE(B5:D5) -> 0.33933293 | H5: =(H28+H51+H74+H97+H120+H143+H166+H189+H212+H235+H258+H281+H304+H327+H350+H373+H396+H419+H442+H465)/100000 -> 2.043 | I5: =(I28+I51+I74+I97+I120+I143+I166+I189+I212+I235+I258+I281+I304+I327+I350+I373+I396+I419+I442+I465)/100000 -> 2.0200004 | J5: =(J28+J51+J74+J97+J120+J143+J166+J189+J212+J235+J258+J281+J304+J327+J350+J373+J396+J419+J442+J465)/100000 -> 0 | K5: =(K28+K51+K74+K97+K120+K143+K166+K189+K212+K235+K258+K281+K304+K327+K350+K373+K396+K419+K442+K465)/100000 -> 0 | L5: =(L28+L51+L74+L97+L120+L143+L166+L189+L212+L235+L258+L281+L304+L327+L350+L373+L396+L419+L442+L465)/100000 -> 0 | M5: =(M28+M51+M74+M97+M120+M143+M166+M189+M212+M235+M258+M281+M304+M327+M350+M373+M396+M419+M442+M465)/100000 -> 0 | N5: =(N28+N51+N74+N97+N120+N143+N166+N189+N212+N235+N258+N281+N304+N327+N350+N373+N396+N419+N442+N465)/100000 -> 0 | O5: =(O28+O51+O74+O97+O120+O143+O166+O189+O212+O235+O258+O281+O304+O327+O350+O373+O396+O419+O442+O465)/100000 -> 0 | P5: =(P28+P51+P74+P97+P120+P143+P166+P189+P212+P235+P258+P281+P304+P327+P350+P373+P396+P419+P442+P465)/100000 -> 0.0229996 | Q5: =(Q28+Q51+Q74+Q97+Q120+Q143+Q166+Q189+Q212+Q235+Q258+Q281+Q304+Q327+Q350+Q373+Q396+Q419+Q442+Q465) -> 0 | R5: =(R28+R51+R74+R97+R120+R143+R166+R189+R212+R235+R258+R281+R304+R327+R350+R373+R396+R419+R442+R465) -> 0 | S5: =(S28+S51+S74+S97+S120+S143+S166+S189+S212+S235+S258+S281+S304+S327+S350+S373+S396+S419+S442+S465) -> 0 | T5: =(T28+T51+T74+T97+T120+T143+T166+T189+T212+T235+T258+T281+T304+T327+T350+T373+T396+T419+T442+T465) -> 0 | U5: =(U28+U51+U74+U97+U120+U143+U166+U189+U212+U235+U258+U281+U304+U327+U350+U373+U396+U419+U442+U465)/100000 -> 2.043 | V5: =(V28+V51+V74+V97+V120+V143+V166+V189+V212+V235+V258+V281+V304+V327+V350+V373+V396+V419+V442+V465)/100000 -> 2.0200004
A6: =IF($A$29="","",$A$29) -> 45200 | B6: =(B29+B52+B75+B98+B121+B144+B167+B190+B213+B236+B259+B282+B305+B328+B351+B374+B397+B420+B443+B466)/100000 -> 0.0149996 | C6: =(C29+C52+C75+C98+C121+C144+C167+C190+C213+C236+C259+C282+C305+C328+C351+C374+C397+C420+C443+C466)/100000 -> 0.0134318 | D6: =(D29+D52+D75+D98+D121+D144+D167+D190+D213+D236+D259+D282+D305+D328+D351+D374+D397+D420+D443+D466)/100000 -> 0.0080018 | E6: =(E29+E52+E75+E98+E121+E144+E167+E190+E213+E236+E259+E282+E305+E328+E351+E374+E397+E420+E443+E466)/100000 -> 0.0070018 | F6: =(F29+F52+F75+F98+F121+F144+F167+F190+F213+F236+F259+F282+F305+F328+F351+F374+F397+F420+F443+F466)/100000 -> 0.0229996 | G6: =AVERAGE(B6:D6) -> 0.0121444 | H6: =(H29+H52+H75+H98+H121+H144+H167+H190+H213+H236+H259+H282+H305+H328+H351+H374+H397+H420+H443+H466)/100000 -> 0.277 | I6: =(I29+I52+I75+I98+I121+I144+I167+I190+I213+I236+I259+I282+I305+I328+I351+I374+I397+I420+I443+I466)/100000 -> 0.2929978 | J6: =(J29+J52+J75+J98+J121+J144+J167+J190+J213+J236+J259+J282+J305+J328+J351+J374+J397+J420+J443+J466)/100000 -> 0 | K6: =(K29+K52+K75+K98+K121+K144+K167+K190+K213+K236+K259+K282+K305+K328+K351+K374+K397+K420+K443+K466)/100000 -> 0 | L6: =(L29+L52+L75+L98+L121+L144+L167+L190+L213+L236+L259+L282+L305+L328+L351+L374+L397+L420+L443+L466)/100000 -> 0 | M6: =(M29+M52+M75+M98+M121+M144+M167+M190+M213+M236+M259+M282+M305+M328+M351+M374+M397+M420+M443+M466)/100000 -> 0 | N6: =(N29+N52+N75+N98+N121+N144+N167+N190+N213+N236+N259+N282+N305+N328+N351+N374+N397+N420+N443+N466)/100000 -> 0 | O6: =(O29+O52+O75+O98+O121+O144+O167+O190+O213+O236+O259+O282+O305+O328+O351+O374+O397+O420+O443+O466)/100000 -> 0 | P6: =(P29+P52+P75+P98+P121+P144+P167+P190+P213+P236+P259+P282+P305+P328+P351+P374+P397+P420+P443+P466)/100000 -> -0.0159978 | Q6: =(Q29+Q52+Q75+Q98+Q121+Q144+Q167+Q190+Q213+Q236+Q259+Q282+Q305+Q328+Q351+Q374+Q397+Q420+Q443+Q466) -> 0 | R6: =(R29+R52+R75+R98+R121+R144+R167+R190+R213+R236+R259+R282+R305+R328+R351+R374+R397+R420+R443+R466) -> 0 | S6: =(S29+S52+S75+S98+S121+S144+S167+S190+S213+S236+S259+S282+S305+S328+S351+S374+S397+S420+S443+S466) -> 0 | T6: =(T29+T52+T75+T98+T121+T144+T167+T190+T213+T236+T259+T282+T305+T328+T351+T374+T397+T420+T443+T466) -> 0 | U6: =(U29+U52+U75+U98+U121+U144+U167+U190+U213+U236+U259+U282+U305+U328+U351+U374+U397+U420+U443+U466)/100000 -> 0.277 | V6: =(V29+V52+V75+V98+V121+V144+V167+V190+V213+V236+V259+V282+V305+V328+V351+V374+V397+V420+V443+V466)/100000 -> 0.2929978
A7: =IF($A$30="","",$A$30) -> 45231 | B7: =(B30+B53+B76+B99+B122+B145+B168+B191+B214+B237+B260+B283+B306+B329+B352+B375+B398+B421+B444+B467)/100000 -> 0.0008768 | C7: =(C30+C53+C76+C99+C122+C145+C168+C191+C214+C237+C260+C283+C306+C329+C352+C375+C398+C421+C444+C467)/100000 -> 0.0008768 | D7: =(D30+D53+D76+D99+D122+D145+D168+D191+D214+D237+D260+D283+D306+D329+D352+D375+D398+D421+D444+D467)/100000 -> 0.0007668 | E7: =(E30+E53+E76+E99+E122+E145+E168+E191+E214+E237+E260+E283+E306+E329+E352+E375+E398+E421+E444+E467)/100000 -> 0.0007668 | F7: =(F30+F53+F76+F99+F122+F145+F168+F191+F214+F237+F260+F283+F306+F329+F352+F375+F398+F421+F444+F467)/100000 -> 0.0120018 | G7: =AVERAGE(B7:D7) -> 0.00084013333 | H7: =(H30+H53+H76+H99+H122+H145+H168+H191+H214+H237+H260+H283+H306+H329+H352+H375+H398+H421+H444+H467)/100000 -> 0.01 | I7: =(I30+I53+I76+I99+I122+I145+I168+I191+I214+I237+I260+I283+I306+I329+I352+I375+I398+I421+I444+I467)/100000 -> 0.016235 | J7: =(J30+J53+J76+J99+J122+J145+J168+J191+J214+J237+J260+J283+J306+J329+J352+J375+J398+J421+J444+J467)/100000 -> 0 | K7: =(K30+K53+K76+K99+K122+K145+K168+K191+K214+K237+K260+K283+K306+K329+K352+K375+K398+K421+K444+K467)/100000 -> 0 | L7: =(L30+L53+L76+L99+L122+L145+L168+L191+L214+L237+L260+L283+L306+L329+L352+L375+L398+L421+L444+L467)/100000 -> 0 | M7: =(M30+M53+M76+M99+M122+M145+M168+M191+M214+M237+M260+M283+M306+M329+M352+M375+M398+M421+M444+M467)/100000 -> 0 | N7: =(N30+N53+N76+N99+N122+N145+N168+N191+N214+N237+N260+N283+N306+N329+N352+N375+N398+N421+N444+N467)/100000 -> 0 | O7: =(O30+O53+O76+O99+O122+O145+O168+O191+O214+O237+O260+O283+O306+O329+O352+O375+O398+O421+O444+O467)/100000 -> 0 | P7: =(P30+P53+P76+P99+P122+P145+P168+P191+P214+P237+P260+P283+P306+P329+P352+P375+P398+P421+P444+P467)/100000 -> -0.006235 | Q7: =(Q30+Q53+Q76+Q99+Q122+Q145+Q168+Q191+Q214+Q237+Q260+Q283+Q306+Q329+Q352+Q375+Q398+Q421+Q444+Q467) -> 0 | R7: =(R30+R53+R76+R99+R122+R145+R168+R191+R214+R237+R260+R283+R306+R329+R352+R375+R398+R421+R444+R467) -> 0 | S7: =(S30+S53+S76+S99+S122+S145+S168+S191+S214+S237+S260+S283+S306+S329+S352+S375+S398+S421+S444+S467) -> 0 | T7: =(T30+T53+T76+T99+T122+T145+T168+T191+T214+T237+T260+T283+T306+T329+T352+T375+T398+T421+T444+T467) -> 0 | U7: =(U30+U53+U76+U99+U122+U145+U168+U191+U214+U237+U260+U283+U306+U329+U352+U375+U398+U421+U444+U467)/100000 -> 0.01 | V7: =(V30+V53+V76+V99+V122+V145+V168+V191+V214+V237+V260+V283+V306+V329+V352+V375+V398+V421+V444+V467)/100000 -> 0.016235
A8: =IF($A$31="","",$A$31) -> 45261 | B8: =(B31+B54+B77+B100+B123+B146+B169+B192+B215+B238+B261+B284+B307+B330+B353+B376+B399+B422+B445+B468)/100000 -> 0.0056968 | C8: =(C31+C54+C77+C100+C123+C146+C169+C192+C215+C238+C261+C284+C307+C330+C353+C376+C399+C422+C445+C468)/100000 -> 0.0056968 | D8: =(D31+D54+D77+D100+D123+D146+D169+D192+D215+D238+D261+D284+D307+D330+D353+D376+D399+D422+D445+D468)/100000 -> 0.0006968 | E8: =(E31+E54+E77+E100+E123+E146+E169+E192+E215+E238+E261+E284+E307+E330+E353+E376+E399+E422+E445+E468)/100000 -> 0.0002668 | F8: =(F31+F54+F77+F100+F123+F146+F169+F192+F215+F238+F261+F284+F307+F330+F353+F376+F399+F422+F445+F468)/100000 -> 0.0056968 | G8: =AVERAGE(B8:D8) -> 0.0040301333 | H8: =(H31+H54+H77+H100+H123+H146+H169+H192+H215+H238+H261+H284+H307+H330+H353+H376+H399+H422+H445+H468)/100000 -> 0.01698 | I8: =(I31+I54+I77+I100+I123+I146+I169+I192+I215+I238+I261+I284+I307+I330+I353+I376+I399+I422+I445+I468)/100000 -> 0.01705 | J8: =(J31+J54+J77+J100+J123+J146+J169+J192+J215+J238+J261+J284+J307+J330+J353+J376+J399+J422+J445+J468)/100000 -> 0 | K8: =(K31+K54+K77+K100+K123+K146+K169+K192+K215+K238+K261+K284+K307+K330+K353+K376+K399+K422+K445+K468)/100000 -> 0 | L8: =(L31+L54+L77+L100+L123+L146+L169+L192+L215+L238+L261+L284+L307+L330+L353+L376+L399+L422+L445+L468)/100000 -> 0 | M8: =(M31+M54+M77+M100+M123+M146+M169+M192+M215+M238+M261+M284+M307+M330+M353+M376+M399+M422+M445+M468)/100000 -> 0 | N8: =(N31+N54+N77+N100+N123+N146+N169+N192+N215+N238+N261+N284+N307+N330+N353+N376+N399+N422+N445+N468)/100000 -> 0 | O8: =(O31+O54+O77+O100+O123+O146+O169+O192+O215+O238+O261+O284+O307+O330+O353+O376+O399+O422+O445+O468)/100000 -> 0 | P8: =(P31+P54+P77+P100+P123+P146+P169+P192+P215+P238+P261+P284+P307+P330+P353+P376+P399+P422+P445+P468)/100000 -> -7e-05 | Q8: =(Q31+Q54+Q77+Q100+Q123+Q146+Q169+Q192+Q215+Q238+Q261+Q284+Q307+Q330+Q353+Q376+Q399+Q422+Q445+Q468) -> 0 | R8: =(R31+R54+R77+R100+R123+R146+R169+R192+R215+R238+R261+R284+R307+R330+R353+R376+R399+R422+R445+R468) -> 0 | S8: =(S31+S54+S77+S100+S123+S146+S169+S192+S215+S238+S261+S284+S307+S330+S353+S376+S399+S422+S445+S468) -> 0 | T8: =(T31+T54+T77+T100+T123+T146+T169+T192+T215+T238+T261+T284+T307+T330+T353+T376+T399+T422+T445+T468) -> 0 | U8: =(U31+U54+U77+U100+U123+U146+U169+U192+U215+U238+U261+U284+U307+U330+U353+U376+U399+U422+U445+U468)/100000 -> 0.01698 | V8: =(V31+V54+V77+V100+V123+V146+V169+V192+V215+V238+V261+V284+V307+V330+V353+V376+V399+V422+V445+V468)/100000 -> 0.01705
